<?xml version="1.0" encoding="UTF-8"?>
<robot name="box_bot">

   <material name="red">
      <color rgba="1.0 0.0 0.0 1" />
   </material>
   <material name="green_light">
      <color rgba="0.0 1.0 0.0 1" />
   </material>
   <material name="green_dark">
      <color rgba="0.0 0.5 0.0 1" />
   </material>
   <material name="blue">
      <color rgba="0.0 0.0 1.0 1" />
   </material>
   <material name="yellow">
      <color rgba="1.0 1.0 0.0 1" />
   </material>
   <material name="black">
      <color rgba="0.0 0.0 0.0 1" />
   </material>
   <material name="white">
      <color rgba="1.0 1.0 1.0 1" />
   </material>
   <material name="box_bot_blue">
      <color rgba="0.088656 0.428691 0.491021 1" />
   </material>
   <material name="silver">
      <color rgba="154 137 146 0.8" />
   </material>

   <link name="base_link" />

   <!-- Body -->

   <link name="chassis">
      
      <visual>
         <geometry>
            <box size="0.6 0.4 0.3" />
         </geometry>
         <material name="box_bot_blue" />
      </visual>
      
      <collision>
         <geometry>
            <box size="0.6 0.4 0.3" />
         </geometry>
      </collision>
      
      <inertial>
         <mass value="0.5" />
         <origin rpy="0 0 0" xyz="0 0 0" />
         <inertia ixx="0.0008333333333333335" ixy="0" ixz="0" iyy="0.0008333333333333335" iyz="0" izz="0.0008333333333333335" />
      </inertial>
   
   </link>
   
   <gazebo reference="chassis">
   <material>Gazebo/Blue</material>
  </gazebo>
   
   <joint name="base_link_joint" type="fixed">
      <origin rpy="0 0 0" xyz="0 0 0" />
      <parent link="base_link" />
      <child link="chassis" />
   </joint>
   
   <!-- Back Wheel Left -->
   
   <link name="back_left_wheel">
   
      <visual>
         <origin rpy="0 1.5707 1.5707" xyz="-0.25 0.15 -0.125" />
         <geometry>
            <cylinder length="0.001" radius="0.035" />
         </geometry>
         <material name="red" />
      </visual>
   
      <collision>
         <origin rpy="0 1.5707 1.5707" xyz="-0.25 0.15 -0.125" />
         <geometry>
            <cylinder length="0.001" radius="0.035" />
         </geometry>
      </collision>
   
      <inertial>
         <origin rpy="0 1.5707 1.5707" xyz="-0.25 0.15 -0.125" />
         <mass value="0.05" />
         <inertia ixx="1.531666666666667e-05" ixy="0" ixz="0" iyy="1.531666666666667e-05" iyz="0" izz="3.0625000000000006e-05" />
      </inertial>
   
   </link>
   
   <gazebo reference="back_left_wheel">
      <kp>1000000000000000000000000000.0</kp>
      <kd>1000000000000000000000000000.0</kd>
      <mu1>10.0</mu1>
      <mu2>10.0</mu2>
      <material>Gazebo/Green</material>
   </gazebo>
   
   <joint name="joint_back_left_wheel" type="continuous">
      <origin rpy="0 0 0" xyz="0 0.05 -0.025" />
      <child link="back_left_wheel" />
      <parent link="chassis" />
      <axis rpy="0 0 0" xyz="0 1 0" />
      <limit effort="10000" velocity="1000" />
      <joint_properties damping="1.0" friction="1.0" />
   </joint>
   
   <!-- Back Wheel Right -->
   
   <link name="back_right_wheel">
     
      <visual>
         <origin rpy="0 1.5707 1.5707" xyz="-0.25 -0.15 -0.125" />
         <geometry>
            <cylinder length="0.001" radius="0.035" />
         </geometry>
         <material name="red" />
      </visual>
     
      <collision>
         <origin rpy="0 1.5707 1.5707" xyz="-0.25 -0.15 -0.125" />
         <geometry>
            <cylinder length="0.001" radius="0.035" />
         </geometry>
      </collision>
     
      <inertial>
         <origin rpy="0 1.5707 1.5707" xyz="-0.25 -0.15 -0.125" />
         <mass value="0.05" />
         <inertia ixx="1.531666666666667e-05" ixy="0" ixz="0" iyy="1.531666666666667e-05" iyz="0" izz="3.0625000000000006e-05" />
      </inertial>
   
   </link>
   
   <gazebo reference="back_right_wheel">
      <kp>1000000000000000000000000000.0</kp>
      <kd>1000000000000000000000000000.0</kd>
      <mu1>10.0</mu1>
      <mu2>10.0</mu2>
      <material>Gazebo/Green</material>
   </gazebo>
   
   
   <joint name="joint_back_right_wheel" type="continuous">
      <origin rpy="0 0 0" xyz="0 -0.05 -0.025" />
      <child link="back_right_wheel" />
      <parent link="chassis" />
      <axis rpy="0 0 0" xyz="0 1 0" />
      <limit effort="10000" velocity="1000" />
      <joint_properties damping="1.0" friction="1.0" />
   </joint>
   
   <!-- Front Wheel Left -->
   
   <link name="front_left_wheel">
   
      <visual>
         <origin rpy="0 1.5707 1.5707" xyz="0.25 0.15 -0.125" />
         <geometry>
            <cylinder length="0.001" radius="0.035" />
         </geometry>
         <material name="red" />
      </visual>
   
      <collision>
         <origin rpy="0 1.5707 1.5707" xyz="0.25 0.15 -0.125" />
         <geometry>
            <cylinder length="0.001" radius="0.035" />
         </geometry>
      </collision>
   
      <inertial>
         <origin rpy="0 1.5707 1.5707" xyz="0.25 0.15 -0.125" />
         <mass value="0.05" />
         <inertia ixx="1.531666666666667e-05" ixy="0" ixz="0" iyy="1.531666666666667e-05" iyz="0" izz="3.0625000000000006e-05" />
      </inertial>
   
   </link>
   
    <gazebo reference="front_left_wheel">
      <kp>1000000000000000000000000000.0</kp>
      <kd>1000000000000000000000000000.0</kd>
      <mu1>10.0</mu1>
      <mu2>10.0</mu2>
      <material>Gazebo/Orange</material>
   </gazebo>
   
   <joint name="joint_front_left_wheel" type="continuous">
      <origin rpy="0 0 0" xyz="0 0.05 -0.025" />
      <child link="front_left_wheel" />
      <parent link="chassis" />
      <axis rpy="0 0 0" xyz="0 1 0" />
      <limit effort="10000" velocity="1000" />
      <joint_properties damping="1.0" friction="1.0" />
   </joint>
   
   <!-- Front Wheel Right -->
   
   <link name="front_right_wheel">
   
      <visual>
         <origin rpy="0 1.5707 1.5707" xyz="0.25 -0.15 -0.125" />
         <geometry>
            <cylinder length="0.001" radius="0.035" />
         </geometry>
         <material name="red" />
      </visual>

      <collision>
         <origin rpy="0 1.5707 1.5707" xyz="0.25 -0.15 -0.125" />
         <geometry>
            <cylinder length="0.001" radius="0.035" />
         </geometry>
      </collision>

      <inertial>
         <origin rpy="0 1.5707 1.5707" xyz="0.25 -0.15 -0.125" />
         <mass value="0.05" />
         <inertia ixx="1.531666666666667e-05" ixy="0" ixz="0" iyy="1.531666666666667e-05" iyz="0" izz="3.0625000000000006e-05" />
      </inertial>

   </link>
   
   <gazebo reference="front_right_wheel">
      <kp>1000000000000000000000000000.0</kp>
      <kd>1000000000000000000000000000.0</kd>
      <mu1>10.0</mu1>
      <mu2>10.0</mu2>
      <material>Gazebo/Orange</material>
   </gazebo>

   <joint name="joint_front_right_wheel" type="continuous">
      <origin rpy="0 0 0" xyz="0 -0.05 -0.025" />
      <child link="front_right_wheel" />
      <parent link="chassis" />
      <axis rpy="0 0 0" xyz="0 1 0" />
      <limit effort="10000" velocity="1000" />
      <joint_properties damping="1.0" friction="1.0" />
   </joint>

   <!-- Caster Wheel Front -->

   <link name="front_yaw_link">

      <visual>
         <origin rpy="0 1.5707 1.5707" xyz="0 0 0" />
         <geometry>
            <cylinder length="0.001" radius="0.0045000000000000005" />
         </geometry>
         <material name="blue" />
      </visual>

      <collision>
         <origin rpy="0 1.5707 1.5707" xyz="0 0 0" />
         <geometry>
            <cylinder length="0.001" radius="0.0045000000000000005" />
         </geometry>
      </collision>

      <inertial>
         <origin rpy="0 1.5707 1.5707" xyz="0 0 0" />
         <mass value="0.001" />
         <inertia ixx="5.145833333333334e-09" ixy="0" ixz="0" iyy="5.145833333333334e-09" iyz="0" izz="1.0125000000000003e-08" />
      </inertial>

   </link>
   
   <gazebo reference="front_yaw_link">
      <material>Gazebo/Blue</material>
   </gazebo>

   <joint name="front_yaw_joint" type="continuous">
      <origin rpy="0 0 0" xyz="0.04 0 -0.05" />
      <parent link="chassis" />
      <child link="front_yaw_link" />
      <axis xyz="0 0 1" />
      <limit effort="1000.0" velocity="100.0" />
      <dynamics damping="0.0" friction="0.1" />
   </joint>

   <link name="front_roll_link">

      <visual>
         <origin rpy="0 1.5707 1.5707" xyz="0 0 0" />
         <geometry>
            <cylinder length="0.001" radius="0.0045000000000000005" />
         </geometry>
         <material name="red" />
      </visual>

      <collision>
         <origin rpy="0 1.5707 1.5707" xyz="0 0 0" />
         <geometry>
            <cylinder length="0.001" radius="0.0045000000000000005" />
         </geometry>
      </collision>

      <inertial>
         <origin rpy="0 1.5707 1.5707" xyz="0 0 0" />
         <mass value="0.001" />
         <inertia ixx="5.145833333333334e-09" ixy="0" ixz="0" iyy="5.145833333333334e-09" iyz="0" izz="1.0125000000000003e-08" />
      </inertial>

   </link>
   
    <gazebo reference="front_roll_link">
      <material>Gazebo/Red</material>
   </gazebo>

   <joint name="front_roll_joint" type="continuous">
      <origin rpy="0 0 0" xyz="0 0 0" />
      <parent link="front_yaw_link" />
      <child link="front_roll_link" />
      <axis xyz="1 0 0" />
      <limit effort="1000.0" velocity="100.0" />
      <dynamics damping="0.0" friction="0.1" />
   </joint>

   <link name="front_pitch_link">

      <visual>
         <origin rpy="0 1.5707 1.5707" xyz="0 0 0" />
         <geometry>
            <sphere radius="0.010" />
         </geometry>
         <material name="green_dark" />
      </visual>

      <collision>
         <origin rpy="0 1.5707 1.5707" xyz="0 0 0" />
         <geometry>
            <sphere radius="0.010" />
         </geometry>
      </collision>

      <inertial>
         <origin rpy="0 1.5707 1.5707" xyz="0 0 0" />
         <mass value="0.001" />
         <inertia ixx="4e-08" ixy="0" ixz="0" iyy="4e-08" iyz="0" izz="4e-08" />
      </inertial>

   </link>

   <gazebo reference="front_pitch_link">
      <kp>1000000000000000000000000000.0</kp>
      <kd>1000000000000000000000000000.0</kd>
      <mu1>0.5</mu1>
      <mu2>0.5</mu2>
      <material>Gazebo/Purple</material>
   </gazebo>

   <joint name="front_pitch_joint" type="continuous">
      <origin rpy="0 0 0" xyz="0 0 0" />
      <parent link="front_roll_link" />
      <child link="front_pitch_link" />
      <axis xyz="0 1 0" />
      <limit effort="1000.0" velocity="100.0" />
      <dynamics damping="0.0" friction="0.1" />

   </joint>

   <!-- Caster Wheel Back -->

   <link name="back_yaw_link">

      <visual>
         <origin rpy="0 1.5707 1.5707" xyz="0 0 0" />
         <geometry>
            <cylinder length="0.001" radius="0.0045000000000000005" />
         </geometry>
         <material name="blue" />
      </visual>

      <collision>
         <origin rpy="0 1.5707 1.5707" xyz="0 0 0" />
         <geometry>
            <cylinder length="0.001" radius="0.0045000000000000005" />
         </geometry>
      </collision>

      <inertial>
         <origin rpy="0 1.5707 1.5707" xyz="0 0 0" />
         <mass value="0.001" />
         <inertia ixx="5.145833333333334e-09" ixy="0" ixz="0" iyy="5.145833333333334e-09" iyz="0" izz="1.0125000000000003e-08" />
      </inertial>

   </link>
   
   <gazebo reference="back_yaw_link">
      <material>Gazebo/Blue</material>
   </gazebo>

   <joint name="back_yaw_joint" type="continuous">
      <origin rpy="0 0 0" xyz="-0.04 0 -0.05" />
      <parent link="chassis" />
      <child link="back_yaw_link" />
      <axis xyz="0 0 1" />
      <limit effort="1000.0" velocity="100.0" />
      <dynamics damping="0.0" friction="0.1" />
   </joint>

   <link name="back_roll_link">

      <visual>
         <origin rpy="0 1.5707 1.5707" xyz="0 0 0" />
         <geometry>
            <cylinder length="0.001" radius="0.0045000000000000005" />
         </geometry>
         <material name="red" />
      </visual>

      <collision>
         <origin rpy="0 1.5707 1.5707" xyz="0 0 0" />
         <geometry>
            <cylinder length="0.001" radius="0.0045000000000000005" />
         </geometry>
      </collision>

      <inertial>
         <origin rpy="0 1.5707 1.5707" xyz="0 0 0" />
         <mass value="0.001" />
         <inertia ixx="5.145833333333334e-09" ixy="0" ixz="0" iyy="5.145833333333334e-09" iyz="0" izz="1.0125000000000003e-08" />
      </inertial>

   </link>
   
   <gazebo reference="back_roll_link">
      <material>Gazebo/Red</material>
   </gazebo>

   <joint name="back_roll_joint" type="continuous">
      <origin rpy="0 0 0" xyz="0 0 0" />
      <parent link="back_yaw_link" />
      <child link="back_roll_link" />
      <axis xyz="1 0 0" />
      <limit effort="1000.0" velocity="100.0" />
      <dynamics damping="0.0" friction="0.1" />
   </joint>

   <link name="back_pitch_link">

      <visual>
         <origin rpy="0 1.5707 1.5707" xyz="0 0 0" />
         <geometry>
            <sphere radius="0.010" />
         </geometry>
         <material name="green_light" />
      </visual>

      <collision>
         <origin rpy="0 1.5707 1.5707" xyz="0 0 0" />
         <geometry>
            <sphere radius="0.010" />
         </geometry>
      </collision>

      <inertial>
         <origin rpy="0 1.5707 1.5707" xyz="0 0 0" />
         <mass value="0.001" />
         <inertia ixx="4e-08" ixy="0" ixz="0" iyy="4e-08" iyz="0" izz="4e-08" />
      </inertial>

   </link>
   
   <gazebo reference="back_pitch_link">
      <kp>1000000000000000000000000000.0</kp>
      <kd>1000000000000000000000000000.0</kd>
      <mu1>0.5</mu1>
      <mu2>0.5</mu2>
      <material>Gazebo/Yellow</material>
   </gazebo>

   <joint name="back_pitch_joint" type="continuous">
      <origin rpy="0 0 0" xyz="0 0 0" />
      <parent link="back_roll_link" />
      <child link="back_pitch_link" />
      <axis xyz="0 1 0" />
      <limit effort="1000.0" velocity="100.0" />
      <dynamics damping="0.0" friction="0.1" />
   </joint>
      
      <!-- Pole -->
   
   <link name="pole_link">

      <visual>
         <origin rpy="0 0 0" xyz="3 0 0" />
         <geometry>
            <cylinder length="1" radius="0.25" />
         </geometry>
         <material name="green_dark" />
      </visual>

      <collision>
         <origin rpy="0 0 0" xyz="3 0 0" />
         <geometry>
            <cylinder length="1" radius="0.25" />
         </geometry>
      </collision>

      <inertial>
         <origin rpy="0 0 0" xyz="3 0 0" />
         <mass value="0.001" />
         <inertia ixx="5.145833333333334e-09" ixy="0" ixz="0" iyy="5.145833333333334e-09" iyz="0" izz="1.0125000000000003e-08" />
      </inertial>

   </link>
   
   <gazebo reference="pole_link">
      <kp>1000000000000000000000000000.0</kp>
      <kd>1000000000000000000000000000.0</kd>
      <mu1>10.0</mu1>
      <mu2>10.0</mu2>
      <material>Gazebo/Green</material>
   </gazebo>

   <joint name="pole_joint" type="fixed">
      <origin rpy="0 0 0" xyz="0 0 0" />
      <parent link="base_link" />
      <child link="pole_link" />
      <axis xyz="1 0 0" />
      <limit effort="1000.0" velocity="100.0" />
      <dynamics damping="0.000000001" friction="0.1" />
   </joint>
   
   <!-- Laser Scan -->

   <link name="laser_scan_link">

      <visual>
         <origin rpy="0 0 0" xyz="0 0 0.0" />
         <geometry>
            <box size="0.02 0.02 0.02" />
         </geometry>
      </visual>

      <collision>
         <origin rpy="0 0 0" xyz="0 0 0.0204" />
         <geometry>
            <box size="0.02 0.02 0.02" />
         </geometry>
      </collision>

      <inertial>
         <mass value="0.01" />
         <origin rpy="0 0 0" xyz="0 0 0.0204" />
         <inertia ixx="6.066578520833334e-06" ixy="0" ixz="0" iyy="6.072950163333333e-06" iyz="0" izz="9.365128684166666e-06" />
      </inertial>

   </link>

   <joint name="laser_scan_link_joint" type="prismatic">
      <origin rpy="0 0 0" xyz="0.0 0.0 0.05" />
      <parent link="chassis" />
      <child link="laser_scan_link" />
      <axis xyz="0 0 1" />
      <limit lower="-0.1" upper="0.0" effort="20.0" velocity="2.0" />
      <dynamics damping="0.1" friction="1.0" />
   </joint>

   <link name="laser_scan_frame" />

   <joint name="laser_scan_frame_joint" type="fixed">
      <origin rpy="0 0 0" xyz="0 0 0.03" />
      <parent link="laser_scan_link" />
      <child link="laser_scan_frame" />
      <axis xyz="0 0 0" />
   </joint>

   <!-- Visual Laser Model to be rotated -->

   <link name="laser_scan_model_link">

      <visual>
         <origin rpy="0 0 0" xyz="0 0 0.125" />
         <geometry>
            <cylinder length="0.0408" radius="0.037493" />
         </geometry>
      </visual>

      <collision>
         <origin rpy="0 0 0" xyz="0 0 0.0204" />
         <geometry>
            <cylinder length="0.0408" radius="0.037493" />
         </geometry>
      </collision>

      <inertial>
         <mass value="0.01" />
         <origin rpy="0 0 0" xyz="0 0 0.0204" />
         <inertia ixx="6.066578520833334e-06" ixy="0" ixz="0" iyy="6.072950163333333e-06" iyz="0" izz="9.365128684166666e-06" />
      </inertial>

   </link>

   <joint name="laser_scan_model_link_joint" type="continuous">
      <origin rpy="0 0 0" xyz="0.0 0.0 0.0" />
      <parent link="laser_scan_link" />
      <child link="laser_scan_model_link" />
      <axis xyz="0 0 1" />
      <limit effort="10.0" velocity="2.0" />
      <dynamics friction="0.01" />
   </joint>

   <gazebo>

      <plugin filename="libgazebo_ros2_control.so" name="gazebo_ros2_control">
         <robot_param_node>/my_robot_state_publisher_node</robot_param_node>
      </plugin>
   </gazebo>
   <gazebo reference="laser_scan_frame">
      <sensor name="sensor_ray" type="ray">
         <pose>0 0 0 0 0 0</pose>
         <ray>
            <scan>
               <horizontal>
                  <samples>200</samples>
                  <resolution>1.0</resolution>
                  <min_angle>-3.14</min_angle>
                  <max_angle>3.14</max_angle>
               </horizontal>
            </scan>
            <range>
               <min>0.1</min>
               <max>5.0</max>
            </range>
         </ray>
         <always_on>true</always_on>
         <visualize>true</visualize>
         <update_rate>100.0</update_rate>
         <plugin name="laser" filename="libgazebo_ros_ray_sensor.so">
            <ros>
               <namespace>/box_bot</namespace>
               <remapping>~/out:=laser_scan</remapping>
            </ros>
            <output_type>sensor_msgs/LaserScan</output_type>
         </plugin>
      </sensor>
   </gazebo>

   <link name="pointcloud_link" />

   <joint name="pointcloud_link_joint" type="fixed">
      <origin rpy="0 0 0" xyz="0.051 0.0 0" />
      <parent link="chassis" />
      <child link="pointcloud_link" />
      <axis xyz="0 0 0" />
   </joint>

   <gazebo reference="pointcloud_link">
      <sensor type="ray" name="pointcloud_sensor">
         <ray>
            <scan>
               <horizontal>
                  <samples>50</samples>
                  <resolution>1.0</resolution>
                  <min_angle>-1.0</min_angle>
                  <max_angle>1.0</max_angle>
               </horizontal>
               <vertical>
                  <samples>50</samples>
                  <resolution>1.0</resolution>
                  <min_angle>-1.0</min_angle>
                  <max_angle>1.0</max_angle>
               </vertical>
            </scan>
            <range>
               <min>0.10</min>
               <max>5.0</max>
               <resolution>0.01</resolution>
            </range>

        <!-- Using gazebo's noise instead of plugin's -->

            <noise>
               <type>gaussian</type>
               <mean>0.0</mean>
               <stddev>0.01</stddev>
            </noise>
         </ray>

       <!-- Using gazebo's update rate instead of plugin's -->

         <update_rate>30</update_rate>
         <plugin name="gazebo_ros_block_laser_controller" filename="libgazebo_ros_ray_sensor.so">
            <!-- Change namespace and output topic so published topic is/rrbot/laser/pointcloud -->
            <ros>
               <namespace>box_bot</namespace>
               <argument>~/out:=pointcloud</argument>
            </ros>
            <!-- Set output to sensor_msgs/PointCloud to get same output type asgazebo_ros_block_laser -->
            <output_type>sensor_msgs/PointCloud</output_type>
            <frame_name>pointcloud_link</frame_name>
            <!-- min_intensity instead of hokuyoMinIntensity -->
            <min_intensity>100.0</min_intensity>
         </plugin>
      </sensor>
   </gazebo>

   <!-- RGB CAMERA -->
 
   <link name="rgb_camera_link_frame" />
 
   <joint name="rgb_camera_link_frame_joint" type="fixed">
      <origin rpy="0 0 0" xyz="0.051 0.0 0.05" />
      <parent link="chassis" />
      <child link="rgb_camera_link_frame" />
      <axis xyz="0 0 0" />
   </joint>
 
   <gazebo reference="rgb_camera_link_frame">
      <sensor name="camera" type="wideanglecamera">
         <camera>
            <horizontal_fov>6.283</horizontal_fov>
            <image>
               <width>320</width>
               <height>240</height>
            </image>
            <clip>
               <near>0.1</near>
               <far>100</far>
            </clip>
            <lens>
               <type>custom</type>
               <custom_function>
                  <c1>1.05</c1>
                  <c2>4</c2>
                  <f>1.0</f>
                  <fun>tan</fun>
               </custom_function>
               <scale_to_hfov>true</scale_to_hfov>
               <cutoff_angle>3.1415</cutoff_angle>
               <env_texture_size>512</env_texture_size>
            </lens>
            <always_on>1</always_on>
            <update_rate>30</update_rate>
         </camera>
         <plugin name="camera_controller" filename="libgazebo_ros_camera.so">
            <cameraName>rgb_camera</cameraName>
            <imageTopicName>image_raw</imageTopicName>
            <cameraInfoTopicName>camera_info</cameraInfoTopicName>
            <frameName>rgb_camera_link_frame</frameName>
            <hackBaseline>0.07</hackBaseline>
         </plugin>
      </sensor>
   </gazebo>

</robot>

